test_anagram (__main__.TestExercice) ... FAIL
test_doubles (__main__.TestExercice) ... ok
test_frequence (__main__.TestExercice) ... ok
test_grades (__main__.TestExercice) ... ok
test_order (__main__.TestExercice) ... ERROR

======================================================================
ERROR: test_order (__main__.TestExercice)
----------------------------------------------------------------------
Traceback (most recent call last):
  File "test_exercice.py", line 19, in test_order
    output = [exercice.order(v) for v in values]
  File "test_exercice.py", line 19, in <listcomp>
    output = [exercice.order(v) for v in values]
  File "/home/runner/work/c04-ch6-exercices-Laure-Anne-Reau/c04-ch6-exercices-Laure-Anne-Reau/exercice.py", line 12, in order
    return sorted(my_list)
UnboundLocalError: local variable 'my_list' referenced before assignment

======================================================================
FAIL: test_anagram (__main__.TestExercice)
----------------------------------------------------------------------
Traceback (most recent call last):
  File "test_exercice.py", line 40, in test_anagram
    'Erreur dans la vérification de l\'anagramme'
AssertionError: Lists differ: [None, None] != [True, False]

First differing element 0:
None
True

- [None, None]
+ [True, False] : Erreur dans la vérification de l'anagramme

----------------------------------------------------------------------
Ran 5 tests in 0.001s

FAILED (failures=1, errors=1)
